<?xml version="1.0" encoding="utf-8"?>
<!-- =================================================================================== -->
<!-- |    This document was autogenerated by xacro from mycobot.urdf.xacro             | -->
<!-- |    EDITING THIS FILE BY HAND IS NOT RECOMMENDED                                 | -->
<!-- =================================================================================== -->
<robot name="mycobot" xmlns:controller="http://playerstage.sourceforge.net/gazebo/xmlschema/#controller" xmlns:interface="http://playerstage.sourceforge.net/gazebo/xmlschema/#interface" xmlns:sensor="http://playerstage.sourceforge.net/gazebo/xmlschema/#sensor">
  <material name="red">
    <color rgba="1.0 0.0 0.0 1.0"/>
  </material>
  <material name="green">
    <color rgba="0.0 1.0 0.0 1.0"/>
  </material>
  <material name="blue">
    <color rgba="0.0 0.0 1.0 1.0"/>
  </material>
  <material name="white">
    <color rgba="1.0 1.0 1.0 1.0"/>
  </material>
  <material name="gray">
    <color rgba="0.9 0.9 0.9 1.0"/>
  </material>
  <!-- Used for fixing robot to Gazebo 'base_link' -->
  <link name="world"/>
  <joint name="base_link_to_world_joint" type="fixed">
    <parent link="world"/>
    <child link="base_link"/>
  </joint>
  <!-- <link name="camera_link"/>
  <joint name="joint_kinect_first" type="fixed">
    <origin xyz="-0.7137 0.215 0.4331" rpy="-0.0415 0.3679 -0.2391" />
    <parent link="world"/>
    <child link="camera_link"/>
  </joint> -->
  <!-- <joint name="joint_rgb_kinect_first" type="fixed">
    <origin rpy="${M_PI/2} ${M_PI} ${M_PI/2}"/>
    <parent link="kinect_first_link"/>
    <child link="kinect_first_rgb_optical_frame"/>
  </joint> -->
  <link name="base_link">
    <visual>
      <geometry>
        <mesh filename="package://mycobot_description/meshes/stl/visual/base_link.dae" scale="0.001 0.001 0.001"/>
      </geometry>
      <origin rpy="0 0 3.14159" xyz="0 0 0"/>

    </visual>
    <collision>
      <geometry>
        <mesh filename="package://mycobot_description/meshes/stl/visual/base_link.stl" scale="0.001 0.001 0.001"/>
      </geometry>
      <origin rpy="0 0 3.14159" xyz="0 0 0"/>
    </collision>
    <inertial>
      <origin rpy="0 0 0" xyz="0 0 0"/>
      <mass value="1.0"/>
      <inertia ixx="6.25083333333e-06" ixy="0" ixz="0" iyy="6.25083333333e-06" iyz="0" izz="1.25e-05"/>
    </inertial>
  </link>
  <joint name="base_joint" type="fixed">
    <origin rpy="0 0 1.570795" xyz="0 0 0.006"/>
    <parent link="base_link"/>
    <child link="link1"/>
  </joint>
  <link name="link1">
    <visual>
      <geometry>
        <mesh filename="package://mycobot_description/meshes/stl/visual/link1.dae"/>
      </geometry>
      <origin rpy="0 0 0" xyz="0 0 0"/>

    </visual>
    <collision>
      <geometry>
        <mesh filename="package://mycobot_description/meshes/stl/collision/link1.stl"/>
        <!-- <mesh filename="package://mycobot_description/meshes/stl/visual/link1.stl" /> -->
      </geometry>
      <origin rpy="0 0 0" xyz="0 0 0"/>
    </collision>
    <inertial>
      <origin rpy="0 0 0" xyz="0 0 0.035"/>
      <mass value="1.0"/>
      <inertia ixx="0.00103333333333" ixy="0" ixz="0" iyy="0.00103333333333" iyz="0" izz="0.00125"/>
    </inertial>
  </link>
  <link name="link2">
    <visual>
      <geometry>
        <mesh filename="package://mycobot_description/meshes/stl/visual/link2.dae"/>
      </geometry>
      <origin rpy="0 0 0" xyz="0 0 0"/>

    </visual>
    <collision>
      <geometry>
        <mesh filename="package://mycobot_description/meshes/stl/collision/link2.stl"/>
        <!-- <mesh filename="package://mycobot_description/meshes/stl/visual/link2.stl" /> -->
      </geometry>
      <origin rpy="0 0 0" xyz="0 0 0"/>
    </collision>
    <inertial>
      <origin rpy="0 0 0" xyz="0 0 0.060"/>
      <mass value="0.2"/>
      <inertia ixx="0.000231666666667" ixy="0" ixz="0" iyy="0.000231666666667" iyz="0" izz="0.00025"/>
    </inertial>
  </link>
  <link name="link3">
    <visual>
      <geometry>
        <mesh filename="package://mycobot_description/meshes/stl/visual/link3.dae"/>
      </geometry>
      <origin rpy="0 0 0" xyz="0 0 0"/>

    </visual>
    <collision>
      <geometry>
        <mesh filename="package://mycobot_description/meshes/stl/collision/link3.stl"/>
        <!-- <mesh filename="package://mycobot_description/meshes/stl/visual/link3.stl" /> -->
      </geometry>
      <origin rpy="0 0 0" xyz="0 0 0"/>
    </collision>
    <inertial>
      <origin rpy="0 0 0" xyz="0.01 0 0.06"/>
      <mass value="0.4"/>
      <inertia ixx="0.00105083333333" ixy="0" ixz="0" iyy="0.00105083333333" iyz="0" izz="0.0005"/>
    </inertial>
  </link>
  <link name="link4">
    <visual>
      <geometry>
        <mesh filename="package://mycobot_description/meshes/stl/visual/link4.dae"/>
      </geometry>
      <origin rpy="0 0 0" xyz="0 0 0"/>

    </visual>
    <collision>
      <geometry>
        <mesh filename="package://mycobot_description/meshes/stl/collision/link4.stl"/>
        <!-- <mesh filename="package://mycobot_description/meshes/stl/visual/link4.stl" /> -->
      </geometry>
      <origin rpy="0 0 0" xyz="0 0 0"/>
    </collision>
    <inertial>
      <origin rpy="0 0 0" xyz="-0.01 0 0.05"/>
      <mass value="0.4"/>
      <inertia ixx="0.00105083333333" ixy="0" ixz="0" iyy="0.00105083333333" iyz="0" izz="0.0005"/>
    </inertial>
  </link>
  <link name="link5">
    <visual>
      <geometry>
        <mesh filename="package://mycobot_description/meshes/stl/visual/link5.dae"/>
      </geometry>
      <origin rpy="0 0 0" xyz="0 0 0"/>

    </visual>
    <collision>
      <geometry>
        <mesh filename="package://mycobot_description/meshes/stl/collision/link5.stl"/>
        <!-- <mesh filename="package://mycobot_description/meshes/stl/visual/link5.stl" /> -->
      </geometry>
      <origin rpy="0 0 0" xyz="0 0 0"/>
    </collision>
    <inertial>
      <origin rpy="0 0 0" xyz="0 0 0.05"/>
      <mass value="0.2"/>
      <inertia ixx="0.000166666666667" ixy="0" ixz="0" iyy="0.000166666666667" iyz="0" izz="0.00025"/>
    </inertial>
  </link>
  <link name="link6">
    <visual>
      <geometry>
        <mesh filename="package://mycobot_description/meshes/stl/visual/link6.dae"/>
      </geometry>
      <origin rpy="0 0 0" xyz="0 0 0 "/>

    </visual>
    <collision>
      <geometry>
        <mesh filename="package://mycobot_description/meshes/stl/collision/link6.stl"/>
        <!-- <mesh filename="package://mycobot_description/meshes/stl/visual/link6.stl" /> -->
      </geometry>
      <origin rpy="0 0 0" xyz="0 0 0"/>
    </collision>
    <inertial>
      <origin rpy="0 0 0" xyz="0 0 0.037"/>
      <mass value="0.5"/>
      <inertia ixx="0.0004625" ixy="0" ixz="0" iyy="0.0004625" iyz="0" izz="0.000625"/>
    </inertial>
  </link>
  <link name="link6_flange">
    <visual>
      <geometry>
        <mesh filename="package://mycobot_description/meshes/stl/visual/link7.dae"/>
      </geometry>
      <origin rpy="0 0 0" xyz="0 0 0 "/>

    </visual>
    <collision>
      <geometry>
        <mesh filename="package://mycobot_description/meshes/stl/collision/link7.stl"/>
      </geometry>
      <origin rpy="0 0 0" xyz="0 0 0"/>
    </collision>
    <inertial>
      <origin rpy="1.570795 0 0" xyz="0 0.0025 0"/>
      <mass value="0.1"/>
      <inertia ixx="1.02083333333e-05" ixy="0" ixz="0" iyy="1.02083333333e-05" iyz="0" izz="2e-05"/>
    </inertial>
  </link>
  <joint name="joint1" type="revolute">
    <axis xyz="0 0 1"/>
    <limit effort="10.0" lower="-3.14159" upper="3.14159" velocity="1.0"/>
    <parent link="link1"/>
    <child link="link2"/>
    <origin rpy="0 0 0" xyz="0 0 0.0706"/>
    <dynamics damping="1.0e-6" friction="2.0e-1"/>
  </joint>
  <joint name="joint2" type="revolute">
    <axis xyz="1 0 0"/>
    <limit effort="10.0" lower="-3.14159" upper="3.14159" velocity="1.0"/>
    <parent link="link2"/>
    <child link="link3"/>
    <origin rpy="0 0 0" xyz="0.03256 0 0.05976"/>
    <dynamics damping="1.0e-6" friction="2.0e-1"/>
  </joint>
  <joint name="joint3" type="revolute">
    <axis xyz="1 0 0"/>
    <limit effort="10.0" lower="-3.14159" upper="3.14159" velocity="1.0"/>
    <parent link="link3"/>
    <child link="link4"/>
    <origin rpy="0 0 0" xyz=" 0.00272 0 0.1104"/>
    <dynamics damping="1.0e-6" friction="2.0e-1"/>
  </joint>
  <joint name="joint4" type="revolute">
    <axis xyz="1 0 0"/>
    <limit effort="10.0" lower="-3.14159" upper="3.14159" velocity="1.0"/>
    <parent link="link4"/>
    <child link="link5"/>
    <origin rpy="0 0 0" xyz="-0.00164 0 0.096"/>
    <dynamics damping="1.0e-6" friction="2.0e-1"/>
  </joint>
  <joint name="joint5" type="revolute">
    <axis xyz="0 0 1"/>
    <limit effort="10.0" lower="-3.14159" upper="3.14159" velocity="1.0"/>
    <parent link="link5"/>
    <child link="link6"/>
    <origin rpy="0 0 0" xyz="0.0298 0 0.02876"/>
    <dynamics damping="1.0e-6" friction="2.0e-1"/>
  </joint>
  <joint name="joint6" type="revolute">
    <axis xyz="0 0 1"/>
    <limit effort="10.0" lower="-3.14159" upper="3.14159" velocity="1.0"/>
    <parent link="link6"/>
    <child link="link6_flange"/>
    <origin rpy="-1.570795 0 0" xyz="0 0.0351 0.03792"/>
    <dynamics damping="1.0e-6" friction="2.0e-1"/>
  </joint>
  <!-- for gazebo simulation -->
  <transmission name="joint1_trans">
    <provideFeedback>true</provideFeedback>
    <implicitSpringDamper>0</implicitSpringDamper>
    <motorTorqueConstant>0.418</motorTorqueConstant>
    <type>transmission_interface/SimpleTransmission</type>
    <joint name="joint1">
      <hardwareInterface>hardware_interface/PositionJointInterface</hardwareInterface>
    </joint>
    <actuator name="joint1_motor">
      <hardwareInterface>hardware_interface/PositionJointInterface</hardwareInterface>
      <mechanicalReduction>1</mechanicalReduction>
    </actuator>
  </transmission>
  <transmission name="joint2_trans">
    <provideFeedback>true</provideFeedback>
    <implicitSpringDamper>0</implicitSpringDamper>
    <motorTorqueConstant>0.418</motorTorqueConstant>
    <type>transmission_interface/SimpleTransmission</type>
    <joint name="joint2">
      <hardwareInterface>hardware_interface/PositionJointInterface</hardwareInterface>
    </joint>
    <actuator name="joint2_motor">
      <hardwareInterface>hardware_interface/PositionJointInterface</hardwareInterface>
      <mechanicalReduction>1</mechanicalReduction>
    </actuator>
  </transmission>
  <transmission name="joint3_trans">
    <provideFeedback>true</provideFeedback>
    <implicitSpringDamper>0</implicitSpringDamper>
    <motorTorqueConstant>0.418</motorTorqueConstant>
    <type>transmission_interface/SimpleTransmission</type>
    <joint name="joint3">
      <hardwareInterface>hardware_interface/PositionJointInterface</hardwareInterface>
    </joint>
    <actuator name="joint3_motor">
      <hardwareInterface>hardware_interface/PositionJointInterface</hardwareInterface>
      <mechanicalReduction>1</mechanicalReduction>
    </actuator>
  </transmission>
  <transmission name="joint4_trans">
    <provideFeedback>true</provideFeedback>
    <implicitSpringDamper>0</implicitSpringDamper>
    <motorTorqueConstant>0.418</motorTorqueConstant>
    <type>transmission_interface/SimpleTransmission</type>
    <joint name="joint4">
      <hardwareInterface>hardware_interface/PositionJointInterface</hardwareInterface>
    </joint>
    <actuator name="joint4_motor">
      <hardwareInterface>hardware_interface/PositionJointInterface</hardwareInterface>
      <mechanicalReduction>1</mechanicalReduction>
    </actuator>
  </transmission>
  <transmission name="joint5_trans">
    <provideFeedback>true</provideFeedback>
    <implicitSpringDamper>0</implicitSpringDamper>
    <motorTorqueConstant>0.418</motorTorqueConstant>
    <type>transmission_interface/SimpleTransmission</type>
    <joint name="joint5">
      <hardwareInterface>hardware_interface/PositionJointInterface</hardwareInterface>
    </joint>
    <actuator name="joint5_motor">
      <hardwareInterface>hardware_interface/PositionJointInterface</hardwareInterface>
      <mechanicalReduction>1</mechanicalReduction>
    </actuator>
  </transmission>
  <transmission name="joint6_trans">
    <provideFeedback>true</provideFeedback>
    <implicitSpringDamper>0</implicitSpringDamper>
    <motorTorqueConstant>0.418</motorTorqueConstant>
    <type>transmission_interface/SimpleTransmission</type>
    <joint name="joint6">
      <hardwareInterface>hardware_interface/PositionJointInterface</hardwareInterface>
    </joint>
    <actuator name="joint6_motor">
      <hardwareInterface>hardware_interface/PositionJointInterface</hardwareInterface>
      <mechanicalReduction>1</mechanicalReduction>
    </actuator>
  </transmission>
  <gazebo reference="link1">
    <material>Gazebo/White</material>
  </gazebo>
  <gazebo reference="link2">
    <material>Gazebo/White</material>
  </gazebo>
  <gazebo reference="link3">
    <material>Gazebo/White</material>
  </gazebo>
  <gazebo reference="link4">
    <material>Gazebo/White</material>
  </gazebo>
  <gazebo reference="link5">
    <material>Gazebo/White</material>
  </gazebo>
  <gazebo reference="link6">
    <material>Gazebo/White</material>
  </gazebo>
  <!-- <xacro:if value="$(arg gazebo_plugin)"> -->
  <gazebo>
    <plugin filename="libgazebo_ros_control.so" name="gazebo_ros_control">
      <robotNamespace></robotNamespace>
      <robotSimType>gazebo_ros_control/DefaultRobotHWSim</robotSimType>
      <legacyModeNS>false</legacyModeNS>
    </plugin>
  </gazebo>
  <!-- </xacro:if> -->
  <mycobot/>
</robot>

